<robot name="robot">
  <link name="base_footprint"></link>
  <joint name="base_joint" type="fixed">
    <parent link="base_footprint" />
    <child link="base_link" />
    <origin xyz="0 0 0.05" rpy="0 0 0" />
  </joint>
  <link name="base_link">
    <visual>
      <origin xyz="0 0 0" rpy="0 0 0" />
      <geometry>
        <box size="0.1 0.1 0.1" />
      </geometry>
      <material name="base_link-material">
        <color rgba="0.010329823026364548 0.11443537381770343 0.45641102317066595 1" />
      </material>
    </visual>
    <collision>
      <origin xyz="0 0 0" rpy="0 0 0" />
      <geometry>
        <box size="0.1 0.1 0.1" />
      </geometry>
    </collision>
    <inertial>
      <origin xyz="0 0 0" rpy="0 0 0" />
      <mass value="1" />
      <inertia ixx="0.16666666666666666" ixy="0" ixz="0" iyy="0.16666666666666666" iyz="0" izz="0.16666666666666666" />
    </inertial>
  </link>
  <joint name="arm_joint_1" type="revolute">
    <parent link="base_link" />
    <child link="arm_1" />
    <origin xyz="0 0 0.1" rpy="0 0 0" />
    <axis xyz="0 0 1"/>
    <limit effort="1000.0" lower="-1" upper="1" velocity="0.5"/>  </joint>
  <link name="arm_1">
    <visual>
      <origin xyz="0 0 0" rpy="0 0 0" />
      <geometry>
        <box size="0.1 0.1 0.1" />
      </geometry>
      <material name="arm_1-material">
        <color rgba="0.12213877222015301 0.3515325994898463 0.8227857543924378 1" />
      </material>
    </visual>
    <collision>
      <origin xyz="0 0 0" rpy="0 0 0" />
      <geometry>
        <box size="0.1 0.1 0.1" />
      </geometry>
    </collision>
    <inertial>
      <origin xyz="0 0 0" rpy="0 0 0" />
      <mass value="1" />
      <inertia ixx="0.16666666666666666" ixy="0" ixz="0" iyy="0.16666666666666666" iyz="0" izz="0.16666666666666666" />
    </inertial>
  </link>
  <joint name="arm_joint_2" type="revolute">
    <parent link="arm_1" />
    <child link="arm_2" />
    <origin xyz="0 0 0.05" rpy="0 0 0" />
    <axis xyz="0 1 0"/>
    <limit effort="1000.0" lower="-1" upper="1" velocity="0.5"/>  </joint>
  <link name="arm_2">
    <visual>
      <origin xyz="0 0 0.1" rpy="0 0 0" />
      <geometry>
        <box size="0.1 0.1 0.2" />
      </geometry>
      <material name="arm_2-material">
        <color rgba="0.010329823026364548 0.11443537381770343 0.45641102317066595 1" />
      </material>
    </visual>
    <collision>
      <origin xyz="0 0 0.1" rpy="0 0 0" />
      <geometry>
        <box size="0.1 0.1 0.2" />
      </geometry>
    </collision>
    <inertial>
      <origin xyz="0 0 0.1" rpy="0 0 0" />
      <mass value="1" />
      <inertia ixx="0.16666666666666666" ixy="0" ixz="0" iyy="0.16666666666666666" iyz="0" izz="0.16666666666666666" />
    </inertial>
  </link>
  <joint name="arm_joint_3" type="revolute">
    <parent link="arm_2" />
    <child link="arm_3" />
    <origin xyz="0 0 0.2" rpy="0 0 0" />
    <axis xyz="0 1 0"/>
    <limit effort="1000.0" lower="0" upper="2" velocity="0.5"/>  </joint>
  <link name="arm_3">
    <visual>
      <origin xyz="0 0 0.1" rpy="0 0 0" />
      <geometry>
        <box size="0.1 0.1 0.2" />
      </geometry>
      <material name="arm_3-material">
        <color rgba="0.31854677811435356 0.5332764040016892 0.8796223968851662 1" />
      </material>
    </visual>
    <collision>
      <origin xyz="0 0 0.1" rpy="0 0 0" />
      <geometry>
        <box size="0.1 0.1 0.2" />
      </geometry>
    </collision>
    <inertial>
      <origin xyz="0 0 0.1" rpy="0 0 0" />
      <mass value="1" />
      <inertia ixx="0.16666666666666666" ixy="0" ixz="0" iyy="0.16666666666666666" iyz="0" izz="0.16666666666666666" />
    </inertial>
  </link>
  <joint name="arm_joint_4" type="revolute">
    <parent link="arm_3" />
    <child link="arm_4" />
    <origin xyz="0 0 0.203411118275279" rpy="0 0 0" />
    <axis xyz="0 -1 0"/>
    <limit effort="1000.0" lower="-2" upper="0" velocity="0.5"/>  </joint>
  <link name="arm_4">
    <visual>
      <origin xyz="0 0 0.1" rpy="0 0 0" />
      <geometry>
        <box size="0.1 0.1 0.2" />
      </geometry>
      <material name="arm_4-material">
        <color rgba="0.010329823026364548 0.11443537381770343 0.45641102317066595 1" />
      </material>
    </visual>
    <collision>
      <origin xyz="0 0 0.1" rpy="0 0 0" />
      <geometry>
        <box size="0.1 0.1 0.2" />
      </geometry>
    </collision>
    <inertial>
      <origin xyz="0 0 0.1" rpy="0 0 0" />
      <mass value="1" />
      <inertia ixx="0.16666666666666666" ixy="0" ixz="0" iyy="0.16666666666666666" iyz="0" izz="0.16666666666666666" />
    </inertial>
  </link>
  <joint name="hand_joint_1" type="revolute">
    <parent link="arm_4" />
    <child link="hand_1" />
    <origin xyz="0 0 0.21" rpy="0 0 0" />
    <axis xyz="0 0 1"/>
    <limit effort="1000.0" lower="-2" upper="2" velocity="0.5"/>  </joint>
  <link name="hand_1">
    <visual>
      <origin xyz="0 0 0" rpy="0 0 0" />
      <geometry>
        <box size="0.1 0.1 0.02" />
      </geometry>
      <material name="hand_1-material">
        <color rgba="0.2746773120495699 0.8713671191959567 0.3712376804636741 1" />
      </material>
    </visual>
    <collision>
      <origin xyz="0 0 0" rpy="0 0 0" />
      <geometry>
        <box size="0.1 0.1 0.02" />
      </geometry>
    </collision>
    <inertial>
      <origin xyz="0 0 0" rpy="0 0 0" />
      <mass value="1" />
      <inertia ixx="0.16666666666666666" ixy="0" ixz="0" iyy="0.16666666666666666" iyz="0" izz="0.16666666666666666" />
    </inertial>
  </link>
  <joint name="hand_joint_2" type="revolute">
    <parent link="hand_1" />
    <child link="hand_2" />
    <origin xyz="0 0 0.01" rpy="0 0 0" />
    <axis xyz="0 1 0"/>
    <limit effort="1000.0" lower="-1" upper="1" velocity="0.5"/>  </joint>
  <link name="hand_2">
    <visual>
      <origin xyz="0 0 0.05" rpy="0 0 0" />
      <geometry>
        <box size="0.02 0.1 0.1" />
      </geometry>
      <material name="hand_2-material">
        <color rgba="0.019382360952473074 0.36130677977297226 0.14126329113044458 1" />
      </material>
    </visual>
    <collision>
      <origin xyz="0 0 0.05" rpy="0 0 0" />
      <geometry>
        <box size="0.02 0.1 0.1" />
      </geometry>
    </collision>
    <inertial>
      <origin xyz="0 0 0.05" rpy="0 0 0" />
      <mass value="1" />
      <inertia ixx="0.16666666666666666" ixy="0" ixz="0" iyy="0.16666666666666666" iyz="0" izz="0.16666666666666666" />
    </inertial>
  </link>
</robot>
