<robot name="robot">
  <link name="base_footprint"></link>
  <joint name="base_joint" type="fixed">
    <parent link="base_footprint" />
    <child link="base_link" />
    <origin xyz="0 0 0.5" rpy="0 0 0" />
  </joint>
  <link name="base_link">
    <visual>
      <origin xyz="0 0 0" rpy="0 0 0" />
      <geometry>
        <box size="1 1 1" />
      </geometry>
      <material name="base_link-material">
        <color rgba="0.010329823026364548 0.11443537381770343 0.45641102317066595 1" />
      </material>
    </visual>
    <collision>
      <origin xyz="0 0 0" rpy="0 0 0" />
      <geometry>
        <box size="1 1 1" />
      </geometry>
    </collision>
    <inertial>
      <origin xyz="0 0 0" rpy="0 0 0" />
      <mass value="1" />
      <inertia ixx="0.16666666666666666" ixy="0" ixz="0" iyy="0.16666666666666666" iyz="0" izz="0.16666666666666666" />
    </inertial>
  </link>
  <joint name="arm_joint_1" type="revolute">
    <parent link="base_link" />
    <child link="arm_1" />
    <origin xyz="0 0 1" rpy="0 0 0" />
    <axis xyz="0 0 1"/>
    <limit effort="1000.0" lower="-1" upper="1" velocity="0.5"/>  </joint>
  <link name="arm_1">
    <visual>
      <origin xyz="0 0 0" rpy="0 0 0" />
      <geometry>
        <box size="1 1 1" />
      </geometry>
      <material name="arm_1-material">
        <color rgba="0.12213877222015301 0.3515325994898463 0.8227857543924378 1" />
      </material>
    </visual>
    <collision>
      <origin xyz="0 0 0" rpy="0 0 0" />
      <geometry>
        <box size="1 1 1" />
      </geometry>
    </collision>
    <inertial>
      <origin xyz="0 0 0" rpy="0 0 0" />
      <mass value="1" />
      <inertia ixx="0.16666666666666666" ixy="0" ixz="0" iyy="0.16666666666666666" iyz="0" izz="0.16666666666666666" />
    </inertial>
  </link>
  <joint name="arm_joint_2" type="revolute">
    <parent link="arm_1" />
    <child link="arm_2" />
    <origin xyz="0 0 0.5" rpy="0 0 0" />
    <axis xyz="0 1 0"/>
    <limit effort="1000.0" lower="-1" upper="1" velocity="0.5"/>  </joint>
  <link name="arm_2">
    <visual>
      <origin xyz="0 0 1" rpy="0 0 0" />
      <geometry>
        <box size="1 1 2" />
      </geometry>
      <material name="arm_2-material">
        <color rgba="0.010329823026364548 0.11443537381770343 0.45641102317066595 1" />
      </material>
    </visual>
    <collision>
      <origin xyz="0 0 1" rpy="0 0 0" />
      <geometry>
        <box size="1 1 2" />
      </geometry>
    </collision>
    <inertial>
      <origin xyz="0 0 1" rpy="0 0 0" />
      <mass value="1" />
      <inertia ixx="0.16666666666666666" ixy="0" ixz="0" iyy="0.16666666666666666" iyz="0" izz="0.16666666666666666" />
    </inertial>
  </link>
  <joint name="arm_joint_3" type="revolute">
    <parent link="arm_2" />
    <child link="arm_3" />
    <origin xyz="0 0 2" rpy="0 0 0" />
    <axis xyz="0 1 0"/>
    <limit effort="1000.0" lower="0" upper="2" velocity="0.5"/>  </joint>
  <link name="arm_3">
    <visual>
      <origin xyz="0 0 1" rpy="0 0 0" />
      <geometry>
        <box size="1 1 2" />
      </geometry>
      <material name="arm_3-material">
        <color rgba="0.31854677811435356 0.5332764040016892 0.8796223968851662 1" />
      </material>
    </visual>
    <collision>
      <origin xyz="0 0 1" rpy="0 0 0" />
      <geometry>
        <box size="1 1 2" />
      </geometry>
    </collision>
    <inertial>
      <origin xyz="0 0 1" rpy="0 0 0" />
      <mass value="1" />
      <inertia ixx="0.16666666666666666" ixy="0" ixz="0" iyy="0.16666666666666666" iyz="0" izz="0.16666666666666666" />
    </inertial>
  </link>
  <joint name="arm_joint_4" type="revolute">
    <parent link="arm_3" />
    <child link="arm_4" />
    <origin xyz="0 0 2.003411118275279" rpy="0 0 0" />
    <axis xyz="0 -1 0"/>
    <limit effort="1000.0" lower="-2" upper="0" velocity="0.5"/>  </joint>
  <link name="arm_4">
    <visual>
      <origin xyz="0 0 1" rpy="0 0 0" />
      <geometry>
        <box size="1 1 2" />
      </geometry>
      <material name="arm_4-material">
        <color rgba="0.010329823026364548 0.11443537381770343 0.45641102317066595 1" />
      </material>
    </visual>
    <collision>
      <origin xyz="0 0 1" rpy="0 0 0" />
      <geometry>
        <box size="1 1 2" />
      </geometry>
    </collision>
    <inertial>
      <origin xyz="0 0 1" rpy="0 0 0" />
      <mass value="1" />
      <inertia ixx="0.16666666666666666" ixy="0" ixz="0" iyy="0.16666666666666666" iyz="0" izz="0.16666666666666666" />
    </inertial>
  </link>
  <joint name="hand_joint_1" type="revolute">
    <parent link="arm_4" />
    <child link="hand_1" />
    <origin xyz="0 0 2.1" rpy="0 0 0" />
    <axis xyz="0 0 1"/>
    <limit effort="1000.0" lower="-2" upper="2" velocity="0.5"/>  </joint>
  <link name="hand_1">
    <visual>
      <origin xyz="0 0 0" rpy="0 0 0" />
      <geometry>
        <box size="1 1 0.2" />
      </geometry>
      <material name="hand_1-material">
        <color rgba="0.2746773120495699 0.8713671191959567 0.3712376804636741 1" />
      </material>
    </visual>
    <collision>
      <origin xyz="0 0 0" rpy="0 0 0" />
      <geometry>
        <box size="1 1 0.2" />
      </geometry>
    </collision>
    <inertial>
      <origin xyz="0 0 0" rpy="0 0 0" />
      <mass value="1" />
      <inertia ixx="0.16666666666666666" ixy="0" ixz="0" iyy="0.16666666666666666" iyz="0" izz="0.16666666666666666" />
    </inertial>
  </link>
  <joint name="hand_joint_2" type="revolute">
    <parent link="hand_1" />
    <child link="hand_2" />
    <origin xyz="0 0 0.1" rpy="0 0 0" />
    <axis xyz="0 1 0"/>
    <limit effort="1000.0" lower="-1" upper="1" velocity="0.5"/>  </joint>
  <link name="hand_2">
    <visual>
      <origin xyz="0 0 0.5" rpy="0 0 0" />
      <geometry>
        <box size="0.2 1 1" />
      </geometry>
      <material name="hand_2-material">
        <color rgba="0.019382360952473074 0.36130677977297226 0.14126329113044458 1" />
      </material>
    </visual>
    <collision>
      <origin xyz="0 0 0.5" rpy="0 0 0" />
      <geometry>
        <box size="0.2 1 1" />
      </geometry>
    </collision>
    <inertial>
      <origin xyz="0 0 0.5" rpy="0 0 0" />
      <mass value="1" />
      <inertia ixx="0.16666666666666666" ixy="0" ixz="0" iyy="0.16666666666666666" iyz="0" izz="0.16666666666666666" />
    </inertial>
  </link>
  <joint name="finger_joint_a1" type="revolute">
    <parent link="hand_2" />
    <child link="finger_a1" />
    <origin xyz="0 -0.4 1" rpy="0 0 0" />
    <axis xyz="0 1 0"/>
    <limit effort="1000.0" lower="0" upper="1" velocity="0.5"/>  </joint>
  <link name="finger_a1">
    <visual>
      <origin xyz="0 0 0.2" rpy="0 0 0" />
      <geometry>
        <box size="0.2 0.2 0.4" />
      </geometry>
      <material name="finger_a1-material">
        <color rgba="0.2746773120495699 0.8713671191959567 0.3712376804636741 1" />
      </material>
    </visual>
    <collision>
      <origin xyz="0 0 0.2" rpy="0 0 0" />
      <geometry>
        <box size="0.2 0.2 0.4" />
      </geometry>
    </collision>
    <inertial>
      <origin xyz="0 0 0.2" rpy="0 0 0" />
      <mass value="1" />
      <inertia ixx="0.16666666666666666" ixy="0" ixz="0" iyy="0.16666666666666666" iyz="0" izz="0.16666666666666666" />
    </inertial>
  </link>
  <joint name="finger_joint_b1" type="revolute">
    <parent link="finger_a1" />
    <child link="finger_b1" />
    <origin xyz="0 0 0.4" rpy="0 0 0" />
    <axis xyz="0 1 0"/>
    <limit effort="1000.0" lower="0" upper="1.5" velocity="0.5"/>  </joint>
  <link name="finger_b1">
    <visual>
      <origin xyz="0 0 0.2" rpy="0 0 0" />
      <geometry>
        <box size="0.2 0.2 0.4" />
      </geometry>
      <material name="finger_b1-material">
        <color rgba="0.019382360952473074 0.36130677977297226 0.14126329113044458 1" />
      </material>
    </visual>
    <collision>
      <origin xyz="0 0 0.2" rpy="0 0 0" />
      <geometry>
        <box size="0.2 0.2 0.4" />
      </geometry>
    </collision>
    <inertial>
      <origin xyz="0 0 0.2" rpy="0 0 0" />
      <mass value="1" />
      <inertia ixx="0.16666666666666666" ixy="0" ixz="0" iyy="0.16666666666666666" iyz="0" izz="0.16666666666666666" />
    </inertial>
  </link>
  <joint name="finger_joint_c1" type="revolute">
    <parent link="finger_b1" />
    <child link="finger_c1" />
    <origin xyz="0 0 0.4" rpy="0 0 0" />
    <axis xyz="0 1 0"/>
    <limit effort="1000.0" lower="0" upper="1" velocity="0.5"/>  </joint>
  <link name="finger_c1">
    <visual>
      <origin xyz="0 0 0.2" rpy="0 0 0" />
      <geometry>
        <box size="0.2 0.2 0.4" />
      </geometry>
      <material name="finger_c1-material">
        <color rgba="0.2746773120495699 0.8713671191959567 0.3712376804636741 1" />
      </material>
    </visual>
    <collision>
      <origin xyz="0 0 0.2" rpy="0 0 0" />
      <geometry>
        <box size="0.2 0.2 0.4" />
      </geometry>
    </collision>
    <inertial>
      <origin xyz="0 0 0.2" rpy="0 0 0" />
      <mass value="1" />
      <inertia ixx="0.16666666666666666" ixy="0" ixz="0" iyy="0.16666666666666666" iyz="0" izz="0.16666666666666666" />
    </inertial>
  </link>
  <joint name="finger_joint_a2" type="revolute">
    <parent link="hand_2" />
    <child link="finger_a2" />
    <origin xyz="0 -0.15 1" rpy="0 0 0" />
    <axis xyz="0 1 0"/>
    <limit effort="1000.0" lower="0" upper="1" velocity="0.5"/>  </joint>
  <link name="finger_a2">
    <visual>
      <origin xyz="0 0 0.2" rpy="0 0 0" />
      <geometry>
        <box size="0.2 0.2 0.4" />
      </geometry>
      <material name="finger_a2-material">
        <color rgba="0.2746773120495699 0.8713671191959567 0.3712376804636741 1" />
      </material>
    </visual>
    <collision>
      <origin xyz="0 0 0.2" rpy="0 0 0" />
      <geometry>
        <box size="0.2 0.2 0.4" />
      </geometry>
    </collision>
    <inertial>
      <origin xyz="0 0 0.2" rpy="0 0 0" />
      <mass value="1" />
      <inertia ixx="0.16666666666666666" ixy="0" ixz="0" iyy="0.16666666666666666" iyz="0" izz="0.16666666666666666" />
    </inertial>
  </link>
  <joint name="finger_joint_b2" type="revolute">
    <parent link="finger_a2" />
    <child link="finger_b2" />
    <origin xyz="0 0 0.4" rpy="0 0 0" />
    <axis xyz="0 1 0"/>
    <limit effort="1000.0" lower="0" upper="1.5" velocity="0.5"/>  </joint>
  <link name="finger_b2">
    <visual>
      <origin xyz="0 0 0.2" rpy="0 0 0" />
      <geometry>
        <box size="0.2 0.2 0.4" />
      </geometry>
      <material name="finger_b2-material">
        <color rgba="0.019382360952473074 0.36130677977297226 0.14126329113044458 1" />
      </material>
    </visual>
    <collision>
      <origin xyz="0 0 0.2" rpy="0 0 0" />
      <geometry>
        <box size="0.2 0.2 0.4" />
      </geometry>
    </collision>
    <inertial>
      <origin xyz="0 0 0.2" rpy="0 0 0" />
      <mass value="1" />
      <inertia ixx="0.16666666666666666" ixy="0" ixz="0" iyy="0.16666666666666666" iyz="0" izz="0.16666666666666666" />
    </inertial>
  </link>
  <joint name="finger_joint_c2" type="revolute">
    <parent link="finger_b2" />
    <child link="finger_c2" />
    <origin xyz="0 0 0.4" rpy="0 0 0" />
    <axis xyz="0 1 0"/>
    <limit effort="1000.0" lower="0" upper="1" velocity="0.5"/>  </joint>
  <link name="finger_c2">
    <visual>
      <origin xyz="0 0 0.2" rpy="0 0 0" />
      <geometry>
        <box size="0.2 0.2 0.4" />
      </geometry>
      <material name="finger_c2-material">
        <color rgba="0.2746773120495699 0.8713671191959567 0.3712376804636741 1" />
      </material>
    </visual>
    <collision>
      <origin xyz="0 0 0.2" rpy="0 0 0" />
      <geometry>
        <box size="0.2 0.2 0.4" />
      </geometry>
    </collision>
    <inertial>
      <origin xyz="0 0 0.2" rpy="0 0 0" />
      <mass value="1" />
      <inertia ixx="0.16666666666666666" ixy="0" ixz="0" iyy="0.16666666666666666" iyz="0" izz="0.16666666666666666" />
    </inertial>
  </link>
  <joint name="finger_joint_a3" type="revolute">
    <parent link="hand_2" />
    <child link="finger_a3" />
    <origin xyz="0 0.14532264788147678 1" rpy="0 0 0" />
    <axis xyz="0 1 0"/>
    <limit effort="1000.0" lower="0" upper="1" velocity="0.5"/>  </joint>
  <link name="finger_a3">
    <visual>
      <origin xyz="0 0 0.2" rpy="0 0 0" />
      <geometry>
        <box size="0.2 0.2 0.4" />
      </geometry>
      <material name="finger_a3-material">
        <color rgba="0.2746773120495699 0.8713671191959567 0.3712376804636741 1" />
      </material>
    </visual>
    <collision>
      <origin xyz="0 0 0.2" rpy="0 0 0" />
      <geometry>
        <box size="0.2 0.2 0.4" />
      </geometry>
    </collision>
    <inertial>
      <origin xyz="0 0 0.2" rpy="0 0 0" />
      <mass value="1" />
      <inertia ixx="0.16666666666666666" ixy="0" ixz="0" iyy="0.16666666666666666" iyz="0" izz="0.16666666666666666" />
    </inertial>
  </link>
  <joint name="finger_joint_b3" type="revolute">
    <parent link="finger_a3" />
    <child link="finger_b3" />
    <origin xyz="0 0 0.4" rpy="0 0 0" />
    <axis xyz="0 1 0"/>
    <limit effort="1000.0" lower="0" upper="1.5" velocity="0.5"/>  </joint>
  <link name="finger_b3">
    <visual>
      <origin xyz="0 0 0.2" rpy="0 0 0" />
      <geometry>
        <box size="0.2 0.2 0.4" />
      </geometry>
      <material name="finger_b3-material">
        <color rgba="0.019382360952473074 0.36130677977297226 0.14126329113044458 1" />
      </material>
    </visual>
    <collision>
      <origin xyz="0 0 0.2" rpy="0 0 0" />
      <geometry>
        <box size="0.2 0.2 0.4" />
      </geometry>
    </collision>
    <inertial>
      <origin xyz="0 0 0.2" rpy="0 0 0" />
      <mass value="1" />
      <inertia ixx="0.16666666666666666" ixy="0" ixz="0" iyy="0.16666666666666666" iyz="0" izz="0.16666666666666666" />
    </inertial>
  </link>
  <joint name="finger_joint_c3" type="revolute">
    <parent link="finger_b3" />
    <child link="finger_c3" />
    <origin xyz="0 0 0.4" rpy="0 0 0" />
    <axis xyz="0 1 0"/>
    <limit effort="1000.0" lower="0" upper="1" velocity="0.5"/>  </joint>
  <link name="finger_c3">
    <visual>
      <origin xyz="0 0 0.2" rpy="0 0 0" />
      <geometry>
        <box size="0.2 0.2 0.4" />
      </geometry>
      <material name="finger_c3-material">
        <color rgba="0.2746773120495699 0.8713671191959567 0.3712376804636741 1" />
      </material>
    </visual>
    <collision>
      <origin xyz="0 0 0.2" rpy="0 0 0" />
      <geometry>
        <box size="0.2 0.2 0.4" />
      </geometry>
    </collision>
    <inertial>
      <origin xyz="0 0 0.2" rpy="0 0 0" />
      <mass value="1" />
      <inertia ixx="0.16666666666666666" ixy="0" ixz="0" iyy="0.16666666666666666" iyz="0" izz="0.16666666666666666" />
    </inertial>
  </link>
  <joint name="finger_joint_a4" type="revolute">
    <parent link="hand_2" />
    <child link="finger_a4" />
    <origin xyz="0 0.4 1" rpy="0 0 0" />
    <axis xyz="0 1 0"/>
    <limit effort="1000.0" lower="0" upper="1" velocity="0.5"/>  </joint>
  <link name="finger_a4">
    <visual>
      <origin xyz="0 0 0.2" rpy="0 0 0" />
      <geometry>
        <box size="0.2 0.2 0.4" />
      </geometry>
      <material name="finger_a4-material">
        <color rgba="0.2746773120495699 0.8713671191959567 0.3712376804636741 1" />
      </material>
    </visual>
    <collision>
      <origin xyz="0 0 0.2" rpy="0 0 0" />
      <geometry>
        <box size="0.2 0.2 0.4" />
      </geometry>
    </collision>
    <inertial>
      <origin xyz="0 0 0.2" rpy="0 0 0" />
      <mass value="1" />
      <inertia ixx="0.16666666666666666" ixy="0" ixz="0" iyy="0.16666666666666666" iyz="0" izz="0.16666666666666666" />
    </inertial>
  </link>
  <joint name="finger_joint_b4" type="revolute">
    <parent link="finger_a4" />
    <child link="finger_b4" />
    <origin xyz="0 0 0.4" rpy="0 0 0" />
    <axis xyz="0 1 0"/>
    <limit effort="1000.0" lower="0" upper="1.5" velocity="0.5"/>  </joint>
  <link name="finger_b4">
    <visual>
      <origin xyz="0 0 0.2" rpy="0 0 0" />
      <geometry>
        <box size="0.2 0.2 0.4" />
      </geometry>
      <material name="finger_b4-material">
        <color rgba="0.019382360952473074 0.36130677977297226 0.14126329113044458 1" />
      </material>
    </visual>
    <collision>
      <origin xyz="0 0 0.2" rpy="0 0 0" />
      <geometry>
        <box size="0.2 0.2 0.4" />
      </geometry>
    </collision>
    <inertial>
      <origin xyz="0 0 0.2" rpy="0 0 0" />
      <mass value="1" />
      <inertia ixx="0.16666666666666666" ixy="0" ixz="0" iyy="0.16666666666666666" iyz="0" izz="0.16666666666666666" />
    </inertial>
  </link>
  <joint name="finger_joint_c4" type="revolute">
    <parent link="finger_b4" />
    <child link="finger_c4" />
    <origin xyz="0 0 0.4" rpy="0 0 0" />
    <axis xyz="0 1 0"/>
    <limit effort="1000.0" lower="0" upper="1" velocity="0.5"/>  </joint>
  <link name="finger_c4">
    <visual>
      <origin xyz="0 0 0.2" rpy="0 0 0" />
      <geometry>
        <box size="0.2 0.2 0.4" />
      </geometry>
      <material name="finger_c4-material">
        <color rgba="0.2746773120495699 0.8713671191959567 0.3712376804636741 1" />
      </material>
    </visual>
    <collision>
      <origin xyz="0 0 0.2" rpy="0 0 0" />
      <geometry>
        <box size="0.2 0.2 0.4" />
      </geometry>
    </collision>
    <inertial>
      <origin xyz="0 0 0.2" rpy="0 0 0" />
      <mass value="1" />
      <inertia ixx="0.16666666666666666" ixy="0" ixz="0" iyy="0.16666666666666666" iyz="0" izz="0.16666666666666666" />
    </inertial>
  </link>
  <joint name="finger_joint_a5" type="revolute">
    <parent link="hand_2" />
    <child link="finger_a5" />
    <origin xyz="0 0.49945761765719277 0.5" rpy="-1.5707963267948963 0 0" />
    <axis xyz="0 1 0"/>
    <limit effort="1000.0" lower="0" upper="2" velocity="0.5"/>  </joint>
  <link name="finger_a5">
    <visual>
      <origin xyz="0 1.1102230246251565e-16 0.09911651863273474" rpy="0 0 0" />
      <geometry>
        <box size="0.2 0.2 0.2" />
      </geometry>
      <material name="finger_a5-material">
        <color rgba="0.2746773120495699 0.8713671191959567 0.3712376804636741 1" />
      </material>
    </visual>
    <collision>
      <origin xyz="0 1.1102230246251565e-16 0.09911651863273474" rpy="0 0 0" />
      <geometry>
        <box size="0.2 0.2 0.2" />
      </geometry>
    </collision>
    <inertial>
      <origin xyz="0 1.1102230246251565e-16 0.09911651863273474" rpy="0 0 0" />
      <mass value="1" />
      <inertia ixx="0.16666666666666666" ixy="0" ixz="0" iyy="0.16666666666666666" iyz="0" izz="0.16666666666666666" />
    </inertial>
  </link>
  <joint name="finger_joint_b5" type="revolute">
    <parent link="finger_a5" />
    <child link="finger_b5" />
    <origin xyz="0 0 0.2" rpy="-3.697785493223493e-32 0 -1.5707963267948963" />
    <axis xyz="0 1 0"/>
    <limit effort="1000.0" lower="0" upper="1" velocity="0.5"/>  </joint>
  <link name="finger_b5">
    <visual>
      <origin xyz="0 0 0.2" rpy="0 0 0" />
      <geometry>
        <box size="0.2 0.2 0.4" />
      </geometry>
      <material name="finger_b5-material">
        <color rgba="0.019382360952473074 0.36130677977297226 0.14126329113044458 1" />
      </material>
    </visual>
    <collision>
      <origin xyz="0 0 0.2" rpy="0 0 0" />
      <geometry>
        <box size="0.2 0.2 0.4" />
      </geometry>
    </collision>
    <inertial>
      <origin xyz="0 0 0.2" rpy="0 0 0" />
      <mass value="1" />
      <inertia ixx="0.16666666666666666" ixy="0" ixz="0" iyy="0.16666666666666666" iyz="0" izz="0.16666666666666666" />
    </inertial>
  </link>
  <joint name="finger_joint_c5" type="revolute">
    <parent link="finger_b5" />
    <child link="finger_c5" />
    <origin xyz="0 0 0.4" rpy="0 0 0" />
    <axis xyz="0 1 0"/>
    <limit effort="1000.0" lower="0" upper="1" velocity="0.5"/>  </joint>
  <link name="finger_c5">
    <visual>
      <origin xyz="0 0 0.2" rpy="0 0 0" />
      <geometry>
        <box size="0.2 0.2 0.4" />
      </geometry>
      <material name="finger_c5-material">
        <color rgba="0.2746773120495699 0.8713671191959567 0.3712376804636741 1" />
      </material>
    </visual>
    <collision>
      <origin xyz="0 0 0.2" rpy="0 0 0" />
      <geometry>
        <box size="0.2 0.2 0.4" />
      </geometry>
    </collision>
    <inertial>
      <origin xyz="0 0 0.2" rpy="0 0 0" />
      <mass value="1" />
      <inertia ixx="0.16666666666666666" ixy="0" ixz="0" iyy="0.16666666666666666" iyz="0" izz="0.16666666666666666" />
    </inertial>
  </link>
</robot>
